commit ef244384966c9d5cc48ab23c300b69aa0ae1b21b
Author: tomc <tomc@cern.ch>
Date:   Mon Mar 11 13:55:58 2019 +0100

    Implementation of 2018 Jet ID

--------------------------------------------------------------------------------------------------

Running test: Run2018-17Sep2018 --> FAILED
Output:   ----- Begin Fatal Exception 11-Mar-2019 13:57:54 CET-----------------------
   An exception of category 'ConfigFileReadError' occurred while
      [0] Processing the python configuration file named ../multilep.py
   Exception Message:
   python encountered the error: <type 'exceptions.RuntimeError'>
   edm::FileInPath unable to find file heavyNeutrino/multilep/data/JECAutumn18_V8_MC_Uncertainty_AK4PFchs.txt anywhere in the search path.
   The search path is defined by: CMSSW_SEARCH_PATH
   ${CMSSW_SEARCH_PATH} is: /storage_mnt/storage/user/tomc/heavyNeutrino/master/CMSSW_10_2_9/src:/storage_mnt/storage/user/tomc/heavyNeutrino/master/CMSSW_10_2_9/external/slc6_amd64_gcc700/data:/cvmfs/cms.cern.ch/slc6_amd64_gcc700/cms/cmssw/CMSSW_10_2_9/src:/cvmfs/cms.cern.ch/slc6_amd64_gcc700/cms/cmssw/CMSSW_10_2_9/external/slc6_amd64_gcc700/data
   Current directory is: /storage_mnt/storage/user/tomc/heavyNeutrino/master/CMSSW_10_2_9/src/heavyNeutrino/multilep/test/testing
   
   ----- End Fatal Exception -------------------------------------------------

--------------------------------------------------------------------------------------------------

Running test: Run2018-PromptReco --> FAILED
Output:   ----- Begin Fatal Exception 11-Mar-2019 13:58:01 CET-----------------------
   An exception of category 'ConfigFileReadError' occurred while
      [0] Processing the python configuration file named ../multilep.py
   Exception Message:
   python encountered the error: <type 'exceptions.RuntimeError'>
   edm::FileInPath unable to find file heavyNeutrino/multilep/data/JECAutumn18_V8_MC_Uncertainty_AK4PFchs.txt anywhere in the search path.
   The search path is defined by: CMSSW_SEARCH_PATH
   ${CMSSW_SEARCH_PATH} is: /storage_mnt/storage/user/tomc/heavyNeutrino/master/CMSSW_10_2_9/src:/storage_mnt/storage/user/tomc/heavyNeutrino/master/CMSSW_10_2_9/external/slc6_amd64_gcc700/data:/cvmfs/cms.cern.ch/slc6_amd64_gcc700/cms/cmssw/CMSSW_10_2_9/src:/cvmfs/cms.cern.ch/slc6_amd64_gcc700/cms/cmssw/CMSSW_10_2_9/external/slc6_amd64_gcc700/data
   Current directory is: /storage_mnt/storage/user/tomc/heavyNeutrino/master/CMSSW_10_2_9/src/heavyNeutrino/multilep/test/testing
   
   ----- End Fatal Exception -------------------------------------------------

--------------------------------------------------------------------------------------------------

Running test: Run2017-31March2017 --> FAILED
Output:   ----- Begin Fatal Exception 11-Mar-2019 13:58:08 CET-----------------------
   An exception of category 'ConfigFileReadError' occurred while
      [0] Processing the python configuration file named ../multilep.py
   Exception Message:
   python encountered the error: <type 'exceptions.NameError'>
   name 'is0217' is not defined
   ----- End Fatal Exception -------------------------------------------------

--------------------------------------------------------------------------------------------------

Running test: Run2016-17Jul2018 --> FAILED
Output:   ----- Begin Fatal Exception 11-Mar-2019 13:58:15 CET-----------------------
   An exception of category 'ConfigFileReadError' occurred while
      [0] Processing the python configuration file named ../multilep.py
   Exception Message:
   python encountered the error: <type 'exceptions.NameError'>
   name 'is0217' is not defined
   ----- End Fatal Exception -------------------------------------------------

--------------------------------------------------------------------------------------------------

Running test: Autumn18MiniAOD --> FAILED
Output:   ----- Begin Fatal Exception 11-Mar-2019 13:58:23 CET-----------------------
   An exception of category 'ConfigFileReadError' occurred while
      [0] Processing the python configuration file named ../multilep.py
   Exception Message:
   python encountered the error: <type 'exceptions.RuntimeError'>
   edm::FileInPath unable to find file heavyNeutrino/multilep/data/JECAutumn18_V8_MC_Uncertainty_AK4PFchs.txt anywhere in the search path.
   The search path is defined by: CMSSW_SEARCH_PATH
   ${CMSSW_SEARCH_PATH} is: /storage_mnt/storage/user/tomc/heavyNeutrino/master/CMSSW_10_2_9/src:/storage_mnt/storage/user/tomc/heavyNeutrino/master/CMSSW_10_2_9/external/slc6_amd64_gcc700/data:/cvmfs/cms.cern.ch/slc6_amd64_gcc700/cms/cmssw/CMSSW_10_2_9/src:/cvmfs/cms.cern.ch/slc6_amd64_gcc700/cms/cmssw/CMSSW_10_2_9/external/slc6_amd64_gcc700/data
   Current directory is: /storage_mnt/storage/user/tomc/heavyNeutrino/master/CMSSW_10_2_9/src/heavyNeutrino/multilep/test/testing
   
   ----- End Fatal Exception -------------------------------------------------

--------------------------------------------------------------------------------------------------

Running test: Fall17MiniAODv2 --> FAILED
Output:   ----- Begin Fatal Exception 11-Mar-2019 13:58:30 CET-----------------------
   An exception of category 'ConfigFileReadError' occurred while
      [0] Processing the python configuration file named ../multilep.py
   Exception Message:
   python encountered the error: <type 'exceptions.NameError'>
   name 'is0217' is not defined
   ----- End Fatal Exception -------------------------------------------------

--------------------------------------------------------------------------------------------------

Running test: Summer16MiniAODv3 --> FAILED
Output:   ----- Begin Fatal Exception 11-Mar-2019 13:58:36 CET-----------------------
   An exception of category 'ConfigFileReadError' occurred while
      [0] Processing the python configuration file named ../multilep.py
   Exception Message:
   python encountered the error: <type 'exceptions.NameError'>
   name 'is0217' is not defined
   ----- End Fatal Exception -------------------------------------------------
